Workbook

Sheet README
A1: Solo5Estrellas.com — SEO / AEO / GEO Master Tracker
A2: Created 6 Oct 2026 from the SEO proposal. Spanish-language luxury hotels: U.S. Spanish, Mexico, Spain, Latin America.
A4: How to use
A5: 1 | B5: Every issue or opportunity is ONE row on 'Master Tracker' (one URL or template, one issue). Seeded rows come from the Oct 2026 audit.
A6: 2 | B6: Blue text = values you type. Black = formulas (do not overwrite). Yellow fill = baseline cells to fill in Week 1 from Search Console, GA4 and Semrush.
A7: 3 | B7: Pick Status, Priority, Impact, Effort, Category, Market from the dropdowns. Allowed statuses: Identified > Approved > Planned > In Progress > Waiting for Client > Waiting for Developer > Testing > Monitoring > Completed.
A8: 4 | B8: 'Executive Dashboard' reads the Master Tracker automatically. KPI baselines and targets are inputs there.
A9: 5 | B9: Specialist tabs (Keywords, Rankings, Content, Hotel Pages, Destination Pages, U.S. Hispanic SEO, International Markets, AEO, GEO - AI Visibility, Schema, Backlinks, Competitors) hold detail; link their rows back to a Master Tracker ID.
A10: 6 | B10: When a row reaches Completed, copy it to 'Completed Work' with the Before and After metric.
A11: Data status
A12: • | B12: No keyword volumes, positions, clicks or impressions are entered. Semrush API units were exhausted and Search Console/GA4 were not yet connected. Cells are blank by design — do not estimate.
A13: • | B13: Priority formula (proposal section 25.3): Score = Demand x Intent x Value x Probability / Effort, each input 1-5. Scored on the Keywords tab.
A14: Review cadence | B14: Daily: indexing and errors. Weekly: GSC, rankings, crawl, AI spot checks. Monthly: KPI review, audit, market and competitor analysis, AI prompt log.
A16: Legend example
A17: Blue | B17: Input you type
A18: Black | B18: Formula
A19: Yellow | B19: Baseline to capture in Week 1
A20: • | B20: GSC data (6 Oct 2026 exports) is loaded on 'GSC Baseline', 'GSC Queries', 'GSC Pages', 'International Markets' and the Executive Dashboard baseline cells. Master Tracker rows X1-X13 (Search Console) and Y1-Y8 (claude-seo crawl) come from those exports.
A21: • | B21: 7 Oct 2026: full Search Console data pulled via SEO Gets (tabs GSC Queries, GSC Pages, GSC Query x Country, GSC Insights). Master Tracker rows Z1-Z8 come from it.

Sheet Executive Dashboard
A1: Executive Dashboard
A2: Task counts read from Master Tracker. KPI baseline and targets are inputs (blue); targets are set after Week 1 baseline.
A4: Tasks by status | D4: Open tasks by priority | G4: Open tasks by category
A5: Status | B5: Tasks | D5: Priority | E5: Open tasks | G5: Category | H5: Open tasks
A6: Identified | B6: =COUNTIF('Master Tracker'!$X$5:$X$300,A6) -> 89 | D6: Critical | E6: =COUNTIFS('Master Tracker'!$Q$5:$Q$300,D6,'Master Tracker'!$X$5:$X$300,"<>Completed",'Master Tracker'!$A$5:$A$300,"<>") -> 19 | G6: Technical | H6: =COUNTIFS('Master Tracker'!$I$5:$I$300,G6,'Master Tracker'!$X$5:$X$300,"<>Completed",'Master Tracker'!$A$5:$A$300,"<>") -> 20
A7: Approved | B7: =COUNTIF('Master Tracker'!$X$5:$X$300,A7) -> 1 | D7: High | E7: =COUNTIFS('Master Tracker'!$Q$5:$Q$300,D7,'Master Tracker'!$X$5:$X$300,"<>Completed",'Master Tracker'!$A$5:$A$300,"<>") -> 49 | G7: Indexing | H7: =COUNTIFS('Master Tracker'!$I$5:$I$300,G7,'Master Tracker'!$X$5:$X$300,"<>Completed",'Master Tracker'!$A$5:$A$300,"<>") -> 16
A8: Planned | B8: =COUNTIF('Master Tracker'!$X$5:$X$300,A8) -> 0 | D8: Medium | E8: =COUNTIFS('Master Tracker'!$Q$5:$Q$300,D8,'Master Tracker'!$X$5:$X$300,"<>Completed",'Master Tracker'!$A$5:$A$300,"<>") -> 37 | G8: Metadata | H8: =COUNTIFS('Master Tracker'!$I$5:$I$300,G8,'Master Tracker'!$X$5:$X$300,"<>Completed",'Master Tracker'!$A$5:$A$300,"<>") -> 5
A9: In Progress | B9: =COUNTIF('Master Tracker'!$X$5:$X$300,A9) -> 0 | D9: Low | E9: =COUNTIFS('Master Tracker'!$Q$5:$Q$300,D9,'Master Tracker'!$X$5:$X$300,"<>Completed",'Master Tracker'!$A$5:$A$300,"<>") -> 16 | G9: Localization | H9: =COUNTIFS('Master Tracker'!$I$5:$I$300,G9,'Master Tracker'!$X$5:$X$300,"<>Completed",'Master Tracker'!$A$5:$A$300,"<>") -> 7
A10: Waiting for Client | B10: =COUNTIF('Master Tracker'!$X$5:$X$300,A10) -> 25 | G10: Schema | H10: =COUNTIFS('Master Tracker'!$I$5:$I$300,G10,'Master Tracker'!$X$5:$X$300,"<>Completed",'Master Tracker'!$A$5:$A$300,"<>") -> 4
A11: Waiting for Developer | B11: =COUNTIF('Master Tracker'!$X$5:$X$300,A11) -> 6 | G11: Internal linking | H11: =COUNTIFS('Master Tracker'!$I$5:$I$300,G11,'Master Tracker'!$X$5:$X$300,"<>Completed",'Master Tracker'!$A$5:$A$300,"<>") -> 2
A12: Testing | B12: =COUNTIF('Master Tracker'!$X$5:$X$300,A12) -> 0 | G12: Content | H12: =COUNTIFS('Master Tracker'!$I$5:$I$300,G12,'Master Tracker'!$X$5:$X$300,"<>Completed",'Master Tracker'!$A$5:$A$300,"<>") -> 56
A13: Monitoring | B13: =COUNTIF('Master Tracker'!$X$5:$X$300,A13) -> 0 | G13: AEO | H13: =COUNTIFS('Master Tracker'!$I$5:$I$300,G13,'Master Tracker'!$X$5:$X$300,"<>Completed",'Master Tracker'!$A$5:$A$300,"<>") -> 1
A14: Completed | B14: =COUNTIF('Master Tracker'!$X$5:$X$300,A14) -> 1 | G14: GEO | H14: =COUNTIFS('Master Tracker'!$I$5:$I$300,G14,'Master Tracker'!$X$5:$X$300,"<>Completed",'Master Tracker'!$A$5:$A$300,"<>") -> 1
A15: Total with an ID | B15: =COUNTA('Master Tracker'!$A$5:$A$300) -> 122 | G15: Entity | H15: =COUNTIFS('Master Tracker'!$I$5:$I$300,G15,'Master Tracker'!$X$5:$X$300,"<>Completed",'Master Tracker'!$A$5:$A$300,"<>") -> 2
A16: Overdue (target passed, not Completed/Monitoring) | B16: =COUNTIFS('Master Tracker'!$W$5:$W$300,"<"&TODAY(),'Master Tracker'!$X$5:$X$300,"<>Completed",'Master Tracker'!$X$5:$X$300,"<>Monitoring",'Master Tracker'!$A$5:$A$300,"<>") -> 14 | G16: Tracking | H16: =COUNTIFS('Master Tracker'!$I$5:$I$300,G16,'Master Tracker'!$X$5:$X$300,"<>Completed",'Master Tracker'!$A$5:$A$300,"<>") -> 1
A17: Completion rate | B17: =IFERROR(B14/B15,0) -> 0.0081967213 | G17: Keywords | H17: =COUNTIFS('Master Tracker'!$I$5:$I$300,G17,'Master Tracker'!$X$5:$X$300,"<>Completed",'Master Tracker'!$A$5:$A$300,"<>") -> 2
G18: Backlinks | H18: =COUNTIFS('Master Tracker'!$I$5:$I$300,G18,'Master Tracker'!$X$5:$X$300,"<>Completed",'Master Tracker'!$A$5:$A$300,"<>") -> 0
G19: Performance | H19: =COUNTIFS('Master Tracker'!$I$5:$I$300,G19,'Master Tracker'!$X$5:$X$300,"<>Completed",'Master Tracker'!$A$5:$A$300,"<>") -> 4
A23: KPI scorecard (fill baseline in Week 1; targets are % change vs baseline)
A24: KPI | B24: Baseline | C24: Current | D24: Change vs baseline | E24: 30-day target | F24: 90-day target | G24: 6-month target | H24: Source
A25: Organic clicks | B25: 124 | D25: =IF(OR(B25="",C25="",B25=0),"",C25/B25-1) | H25: GSC
A26: Organic impressions | B26: 45837 | D26: =IF(OR(B26="",C26="",B26=0),"",C26/B26-1) | H26: GSC
A27: CTR | B27: 0.0027052381 | D27: =IF(OR(B27="",C27="",B27=0),"",C27/B27-1) | H27: GSC
A28: Average position | B28: 17.8 | D28: =IF(OR(B28="",C28="",B28=0),"",C28/B28-1) | H28: GSC
A29: Keywords in top 3 | B29: 91 | D29: =IF(OR(B29="",C29="",B29=0),"",C29/B29-1) | H29: GSC queries by avg position (SEO Gets, 29 Jan-3 Oct); includes 1-impression queries
A30: Keywords in top 10 | B30: 906 | D30: =IF(OR(B30="",C30="",B30=0),"",C30/B30-1) | H30: GSC queries by avg position (SEO Gets, 29 Jan-3 Oct); includes 1-impression queries
A31: Keywords in top 20 | B31: 2662 | D31: =IF(OR(B31="",C31="",B31=0),"",C31/B31-1) | H31: GSC queries by avg position (SEO Gets, 29 Jan-3 Oct); includes 1-impression queries
A32: Non-brand clicks | B32: 121 | D32: =IF(OR(B32="",C32="",B32=0),"",C32/B32-1) | H32: GSC: total minus brand-query clicks (approx.)
A33: Branded clicks | B33: 3 | D33: =IF(OR(B33="",C33="",B33=0),"",C33/B33-1) | H33: GSC
A34: Indexed pages (high-value) | B34: 5774 | D34: =IF(OR(B34="",C34="",B34=0),"",C34/B34-1) | H34: GSC page indexing: all indexed pages (19 Sep 2026), not only high-value
A35: Organic conversions (inquiries) | D35: =IF(OR(B35="",C35="",B35=0),"",C35/B35-1) | H35: GA4
A36: Booking searches | D36: =IF(OR(B36="",C36="",B36=0),"",C36/B36-1) | H36: GA4
A37: Hotel inquiries | D37: =IF(OR(B37="",C37="",B37=0),"",C37/B37-1) | H37: GA4 / CRM
A38: Revenue from organic ($) | D38: =IF(OR(B38="",C38="",B38=0),"",C38/B38-1) | H38: Booking system
A39: AI citations per month | D39: =IF(OR(B39="",C39="",B39=0),"",C39/B39-1) | H39: Prompt log. GSC shows 1,343 AI-feature impressions since 18 May 2026
A40: Featured snippets | D40: =IF(OR(B40="",C40="",B40=0),"",C40/B40-1) | H40: Semrush
A41: Referring domains | D41: =IF(OR(B41="",C41="",B41=0),"",C41/B41-1) | H41: Semrush / Ahrefs
A42: U.S. Spanish organic sessions | D42: =IF(OR(B42="",C42="",B42=0),"",C42/B42-1) | H42: GA4 + GSC
A43: Latin America organic sessions | D43: =IF(OR(B43="",C43="",B43=0),"",C43/B43-1) | H43: GA4
A45: Baselines for clicks, impressions, CTR, position, brand split and indexed pages come from the 6 Oct 2026 GSC exports (29 Jan - 3 Oct 2026). Other baselines remain blank until GA4/Semrush data is available. No rankings are promised.

Sheet Master Tracker
A1: Master Tracker
A2: One row per URL/template + issue. Blue = type here; CTR is a formula.
A4: ID | B4: Date identified | C4: Market | D4: Country | E4: Language/locale | F4: URL | G4: Page type | H4: Issue/opportunity | I4: Category | J4: Keyword | K4: Search intent | L4: Search volume | M4: Current position | N4: Baseline clicks | O4: Baseline impressions | P4: CTR | Q4: Priority | R4: Impact | S4: Effort | T4: Recommended action | U4: Assigned owner | V4: Date started | W4: Target completion | X4: Status | Y4: Completion date | Z4: Before metric | AA4: After metric | AB4: KPI affected | AC4: Search Console status | AD4: Indexing status | AE4: AI visibility | AF4: Notes | AG4: Next review date
A5: T1 | B5: 46301 | C5: All Spanish | D5: All | E5: es | F5: All indexable templates | G5: Site-wide | H5: No canonical tags on any of 17 sampled templates | I5: Technical | P5: =IFERROR(N5/O5,"") | Q5: Critical | R5: High | S5: S | T5: Add self-referencing absolute canonical to every indexable URL | U5: Dev | W5: 46307 | X5: Waiting for Developer | AB5: Duplicate-canonical flags in GSC to 0 | AF5: Sampled 6 Oct 2026 | EOD 2026-10-06: Spec ready; needs developer | AG5: 46308
A6: T2 | B6: 46301 | C6: All Spanish | D6: All | E6: es | F6: solo5estrellas.com / www.solo5estrellas.com | G6: Site-wide | H6: Apex and www both return 200; http redirects with 302 | I6: Technical | P6: =IFERROR(N6/O6,"") | Q6: Critical | R6: High | S6: S | T6: One canonical host; 301 for http and the alternate host | U6: Dev | W6: 46307 | X6: Waiting for Developer | AB6: One host in GSC | AF6: EOD 2026-10-06: Spec ready; needs hosting/DNS access | AG6: 46308
A7: T3 | B7: 46301 | C7: All Spanish | D7: All | E7: es | F7: /cities/{id}/{any-slug}.html | G7: City | H7: Any slug resolves with 200 (e.g. /cities/192/anything.html) | I7: Indexing | P7: =IFERROR(N7/O7,"") | Q7: Critical | R7: High | S7: M | T7: 301 to canonical slug; real 404 when ID unknown | U7: Dev | W7: 46307 | X7: Waiting for Developer | AB7: Duplicate URLs to 0 | AF7: EOD 2026-10-06: Spec ready; needs developer | AG7: 46308
A8: T4 | B8: 46301 | C8: All Spanish | D8: All | E8: es | F8: /cities/9999/foo.html | G8: City | H8: Soft 404: unknown ID returns 200 | I8: Indexing | P8: =IFERROR(N8/O8,"") | Q8: Critical | R8: High | S8: S | T8: Return 404/410 for missing IDs | U8: Dev | W8: 46307 | X8: Identified | AB8: Soft-404 count in GSC | AG8: 46308
A9: T5 | B9: 46301 | C9: All Spanish | D9: All | E9: es | F9: /sitemap.xml | G9: Sitemap/robots | H9: Sitemap lists 14 URLs; no hotel, city, chain or region URLs | I9: Indexing | P9: =IFERROR(N9/O9,"") | Q9: Critical | R9: High | S9: M | T9: Segmented sitemap index with real lastmod; submit in GSC and Bing | U9: Dev | W9: 46311 | X9: Waiting for Developer | AB9: Indexed vs submitted URLs by type | AF9: EOD 2026-10-06: Spec ready; needs developer | AG9: 46308
A10: T6 | B10: 46301 | C10: All Spanish | D10: All | E10: es | F10: /collection/ and /luxury_hotels/; /chains/2/ and /collection/2/ | G10: Collection | H10: Duplicate hub URLs (identical content) | I10: Indexing | P10: =IFERROR(N10/O10,"") | Q10: High | R10: Medium | S10: S | T10: Choose one URL, 301 the other | U10: Dev | W10: 46311 | X10: Identified | AB10: Duplicate URLs to 0 | AG10: 46308
A11: T7 | B11: 46301 | C11: All Spanish | D11: All | E11: es | F11: /robots.txt | G11: Sitemap/robots | H11: No Sitemap: line | I11: Indexing | P11: =IFERROR(N11/O11,"") | Q11: Medium | R11: Medium | S11: S | T11: Add sitemap index URL | U11: Dev | W11: 46311 | X11: Identified | AB11: Sitemap fetch status | AG11: 46308
A12: T8 | B12: 46301 | C12: All Spanish | D12: All | E12: es | F12: /sitemap/ (footer link) | G12: Site-wide | H12: Footer link returns 404 | I12: Technical | P12: =IFERROR(N12/O12,"") | Q12: High | R12: Medium | S12: S | T12: Create HTML sitemap or remove link | U12: Dev | W12: 46314 | X12: Identified | AB12: 404 internal links to 0 | AG12: 46308
A13: T9 | B13: 46301 | C13: All Spanish | D13: All | E13: es | F13: /cities/192/new_york.html; /cities/44/cancun.html | G13: City | H13: ~3.6 s server response on city pages (others ~0.6 s) | I13: Performance | P13: =IFERROR(N13/O13,"") | Q13: High | R13: Medium | S13: M | T13: Cache and lazy-load hotel lists | U13: Dev | W13: 46321 | X13: Identified | AB13: TTFB under 0.8 s | AG13: 46308
A14: T10 | B14: 46301 | C14: All Spanish | D14: All | E14: es | F14: /regions/8/europe.html | G14: Region | H14: 1,075 links and 199 KB HTML on one page | I14: Internal linking | P14: =IFERROR(N14/O14,"") | Q14: Medium | R14: Medium | S14: M | T14: Group by city; cap links per page | U14: Dev | W14: 46328 | X14: Identified | AB14: Links per page under 300 | AG14: 46308
A15: T11 | B15: 46301 | C15: All Spanish | D15: All | E15: es | F15: Site-wide | G15: Site-wide | H15: Outdated jQuery 1.11.2, Facebook SDK v2.8 | I15: Performance | P15: =IFERROR(N15/O15,"") | Q15: Medium | R15: Low | S15: M | T15: Upgrade or remove | U15: Dev | W15: 46335 | X15: Identified | AB15: Lighthouse mobile score | AG15: 46308
A16: T12 | B16: 46301 | C16: All Spanish | D16: All | E16: es | F16: Site-wide | G16: Site-wide | H16: CFID cookie set for 30 years on every request | I16: Technical | P16: =IFERROR(N16/O16,"") | Q16: Low | R16: Low | S16: S | T16: Session cookies set only after interaction | U16: Dev | W16: 46335 | X16: Identified | AG16: 46308
A17: M1 | B17: 46301 | C17: All Spanish | D17: All | E17: es | F17: All templates | G17: Site-wide | H17: Identical meta description on every page; generic titles | I17: Metadata | P17: =IFERROR(N17/O17,"") | Q17: Critical | R17: High | S17: S | T17: Title and description templates per page type | U17: Dev + Editor | W17: 46311 | X17: Identified | AB17: Unique titles/descriptions 100%; CTR | AG17: 46308
A18: M2 | B18: 46301 | C18: All Spanish | D18: All | E18: es | F18: /collection/, /destinations/, /faq.cfm, /company.cfm, /testimonials.cfm, /guarantee.cfm | G18: Site-wide | H18: English titles on Spanish pages | I18: Localization | P18: =IFERROR(N18/O18,"") | Q18: High | R18: High | S18: S | T18: Translate titles and H1s | U18: Editor | W18: 46311 | X18: Identified | AB18: Impressions on Spanish queries | AG18: 46308
A19: M3 | B19: 46301 | C19: All Spanish | D19: All | E19: es | F19: City template | G19: City | H19: City pages titled 'Bienvenido' | I19: Metadata | P19: =IFERROR(N19/O19,"") | Q19: Critical | R19: High | S19: S | T19: Title: Hoteles de lujo en {ciudad}: los mejores 5 estrellas | U19: Dev | W19: 46311 | X19: Identified | AB19: City-page impressions | AG19: 46308
A20: H1 | B20: 46301 | C20: All Spanish | D20: All | E20: es | F20: Region and hub pages | G20: Region | H20: hreflang es points to homepage, x-default to English homepage on every page | I20: Technical | P20: =IFERROR(N20/O20,"") | Q20: High | R20: Medium | S20: M | T20: Page-level reciprocal es/en pairs with WhataHotel | U20: Dev | W20: 46314 | X20: Identified | AB20: hreflang errors to 0 | AG20: 46308
A21: H2 | B21: 46301 | C21: All Spanish | D21: All | E21: es | F21: City template | G21: City | H21: Malformed hreflang es tag (no ID, no closing quote) | I21: Technical | P21: =IFERROR(N21/O21,"") | Q21: Critical | R21: Medium | S21: S | T21: Remove or repair immediately | U21: Dev | W21: 46304 | X21: Identified | AB21: Valid head markup | AG21: 46308
A22: L1 | B22: 46301 | C22: All Spanish | D22: All | E22: es | F22: Booking loader and offer text | G22: Hotel | H22: Mixed tú/usted ('Reserva tu habitación' vs 'Reciba') | I22: Localization | P22: =IFERROR(N22/O22,"") | Q22: High | R22: Medium | S22: S | T22: Use usted throughout | U22: Editor | W22: 46318 | X22: Identified | AB22: Native-review error count | AF22: 7 Oct: rule in style-guide/ES-STYLE-GUIDE-v1.md | AG22: 46308
A23: L2 | B23: 46301 | C23: All Spanish | D23: All | E23: es | F23: Hotel template (schema offer) | G23: Hotel | H23: Typo 'Reciba Una Nnoche Gratis' | I23: Localization | P23: =IFERROR(N23/O23,"") | Q23: High | R23: Medium | S23: S | T23: Fix wording and sentence case | U23: Editor | W23: 46318 | X23: Identified | AF23: 7 Oct: rule in style-guide/ES-STYLE-GUIDE-v1.md | AG23: 46308
A24: L3 | B24: 46301 | C24: All Spanish | D24: All | E24: es | F24: Occupancy selector | G24: Hotel | H24: '1 Alojamiento, 2 Adulta' wrong noun and plural | I24: Localization | P24: =IFERROR(N24/O24,"") | Q24: High | R24: Medium | S24: S | T24: '1 habitación, 2 adultos' | U24: Editor | W24: 46318 | X24: Identified | AB24: Availability-search rate | AF24: 7 Oct: rule in style-guide/ES-STYLE-GUIDE-v1.md | AG24: 46308
A25: L4 | B25: 46301 | C25: Mexico | D25: Mexico | E25: es | F25: City H1 and nav | G25: City | H25: 'Cancun' without accent | I25: Localization | P25: =IFERROR(N25/O25,"") | Q25: Medium | R25: Medium | S25: S | T25: Use 'Cancún' everywhere | U25: Editor | W25: 46318 | X25: Identified | AB25: Impressions on 'Cancún' queries | AF25: 7 Oct: rule in style-guide/ES-STYLE-GUIDE-v1.md | AG25: 46308
A26: L5 | B26: 46301 | C26: All Spanish | D26: All | E26: es | F26: Language toggle | G26: Site-wide | H26: Toggle labelled 'Spanish / English' on a Spanish page | I26: Localization | P26: =IFERROR(N26/O26,"") | Q26: Low | R26: Low | S26: S | T26: 'Español / English' | U26: Dev | W26: 46318 | X26: Identified | AF26: 7 Oct: rule in style-guide/ES-STYLE-GUIDE-v1.md | AG26: 46308
A27: L6 | B27: 46301 | C27: All Spanish | D27: All | E27: es | F27: Site-wide | G27: Site-wide | H27: Possible encoding corruption in hotel schema text | I27: Technical | P27: =IFERROR(N27/O27,"") | Q27: Medium | R27: Medium | S27: S | T27: Verify UTF-8 end to end | U27: Dev | W27: 46314 | X27: Identified | AF27: To verify | AG27: 46308
A28: S1 | B28: 46301 | C28: All Spanish | D28: All | E28: es | F28: Site-wide | G28: Site-wide | H28: Organization sameAs points to WhataHotel profiles; no Lorraine Travel parent | I28: Schema | P28: =IFERROR(N28/O28,"") | Q28: High | R28: High | S28: S | T28: Rebuild Organization graph with parentOrganization | U28: Dev + SEO | W28: 46311 | X28: Identified | AB28: Valid entity graph | AG28: 46308
A29: S2 | B29: 46301 | C29: All Spanish | D29: All | E29: es | F29: /hotels/{id}/ | G29: Hotel | H29: No Hotel/LodgingBusiness schema; zero-price Offer markup | I29: Schema | P29: =IFERROR(N29/O29,"") | Q29: High | R29: Medium | S29: M | T29: Add Hotel entity; remove zero-price offers | U29: Dev + SEO | W29: 46321 | X29: Identified | AB29: Schema errors to 0 | AG29: 46308
A30: S3 | B30: 46301 | C30: All Spanish | D30: All | E30: es | F30: Hotel, city, chain | G30: Hotel | H30: No breadcrumbs or BreadcrumbList | I30: Schema | P30: =IFERROR(N30/O30,"") | Q30: High | R30: Medium | S30: M | T30: Visible breadcrumbs plus schema | U30: Dev | W30: 46314 | X30: Identified | AB30: Breadcrumb coverage | AG30: 46308
A31: E1 | B31: 46301 | C31: All Spanish | D31: All | E31: es | F31: /company.cfm | G31: Company | H31: About page: English title, no H1, no named experts | I31: Entity | P31: =IFERROR(N31/O31,"") | Q31: High | R31: High | S31: M | T31: Rebuild About Lorraine Travel; advisor profiles | U31: Client + Editor | W31: 46325 | X31: Identified | AB31: Page indexed; branded impressions | AG31: 46308
A32: C1 | B32: 46301 | C32: United States - Spanish | D32: United States | E32: es | F32: New (Spanish path) | G32: City | H32: No Miami hub | I32: Content | P32: =IFERROR(N32/O32,"") | Q32: High | R32: High | S32: M | T32: Launch Miami hub from city template | U32: Editor | W32: 46321 | X32: Waiting for Client | AB32: Impressions; top-10 hub keywords | AF32: Demand to validate | 7 Oct: drafts in content/miami/ and content/nueva-york/; needs zone check, reviewer, perks date | AG32: 46308
A33: C2 | B33: 46301 | C33: United States - Spanish | D33: United States | E33: es | F33: /cities/192/new_york.html | G33: City | H33: New York page is a listing (74 hotels, 'Bienvenido' title) | I33: Content | P33: =IFERROR(N33/O33,"") | Q33: High | R33: High | S33: M | T33: Rebuild with hub template | U33: Editor | W33: 46318 | X33: Waiting for Client | AB33: Top-10 keywords | AF33: 7 Oct: drafts in content/miami/ and content/nueva-york/; needs zone check, reviewer, perks date | AG33: 46308
A34: C3 | B34: 46301 | C34: Mexico | D34: Mexico | E34: es | F34: /cities/44/cancun.html | G34: City | H34: Cancún page is a listing | I34: Content | P34: =IFERROR(N34/O34,"") | Q34: High | R34: High | S34: M | T34: Rebuild with hub template | U34: Editor | W34: 46318 | X34: Identified | AB34: Top-10 keywords | AG34: 46308
A35: C4 | B35: 46301 | C35: United States - Spanish | D35: United States | E35: es | F35: /chains/2/four_seasons.html | G35: Chain | H35: Four Seasons perks unsourced and undated | I35: Content | P35: =IFERROR(N35/O35,"") | Q35: High | R35: High | S35: M | T35: Rebuild with sourced perks, FAQ, comparison | U35: Editor | W35: 46321 | X35: Identified | AB35: Impressions 'hoteles Four Seasons' | AG35: 46308
A36: A1 | B36: 46301 | C36: All Spanish | D36: All | E36: es | F36: /faq.cfm | G36: FAQ | H36: No benefits/FAQ hub with direct answers | I36: AEO | P36: =IFERROR(N36/O36,"") | Q36: High | R36: High | S36: M | T36: 15 direct answers (40-60 words) with sources | U36: Editor | W36: 46325 | X36: Identified | AB36: Snippet/PAA entries | AG36: 46308
A37: G1 | B37: 46301 | C37: All Spanish | D37: All | E37: es | F37: Research | G37: Site-wide | H37: No AI-visibility baseline | I37: GEO | P37: =IFERROR(N37/O37,"") | Q37: High | R37: Medium | S37: S | T37: Run 40-prompt baseline across 5 AI systems | U37: SEO | W37: 46325 | X37: Identified | AB37: AI citations | AG37: 46308
A38: K1 | B38: 46301 | C38: All Spanish | D38: All | E38: es | F38: Research | G38: Site-wide | H38: No keyword or competitor data (Semrush units exhausted) | I38: Keywords | P38: =IFERROR(N38/O38,"") | Q38: High | R38: High | S38: S | T38: Restore API units or use alternative tool | U38: Client | W38: 46304 | X38: Waiting for Client | AB38: Keyword set available | AF38: EOD 2026-10-06: Semrush API units exhausted; client to restore units or approve alternative tool | AG38: 46308
A39: TR1 | B39: 46301 | C39: All Spanish | D39: All | E39: es | F39: GA4 / GTM | G39: Site-wide | H39: Conversion events not verified | I39: Tracking | P39: =IFERROR(N39/O39,"") | Q39: Critical | R39: High | S39: M | T39: Audit/add hotel_search, availability_search, booking_click, inquiry_submit, phone/email click, special_offer_click | U39: Dev + SEO | W39: 46307 | X39: Waiting for Client | AB39: Events firing | AF39: EOD 2026-10-06: Needs GA4 + GTM access to audit and add events | AG39: 46308
A40: X1 | B40: 46301 | C40: United States - Spanish | D40: All | E40: es | F40: /browse_country.cfm?countryid=64 (Turks & Caicos country hub) | G40: Country | H40: Top URL in GSC is a legacy parameter URL: 29 of 124 clicks (23%) and 8,384 impressions (18%) at position 11.8, CTR 0.35% | I40: Indexing | N40: 29 | O40: 8384 | P40: =IFERROR(N40/O40,"") -> 0.0034589695 | Q40: Critical | R40: High | S40: M | T40: 301 legacy browse_*.cfm?id URLs to canonical /countries/{id}/ pages; rebuild the Turks & Caicos hub (Spanish name 'Islas Turcas y Caicos', 'Turks and Caicos' variant) to reach top 5 | U40: Dev + Editor | W40: 46311 | X40: Waiting for Developer | AB40: Clicks and CTR on Turks & Caicos queries | AC40: From GSC export 6 Oct 2026 | AF40: Queries: hoteles en islas turcas y caicos (1,283 impr, pos 10.9, 0 clicks); 65 Turks & Caicos query variants = 5,692 impr | 7 Oct: 301 browse_country.cfm?countryid=64 to the new hub after it is live; see IMPLEMENTATION-NOTES.md | AG40: 46308
A41: X2 | B41: 46301 | C41: All Spanish | D41: All | E41: es | F41: /browse_hotel.cfm?hotelID=, /browse_city.cfm?cityid=, /browse_region.cfm?regionid= | G41: Search/filter | H41: 11 legacy browse_*.cfm?id URLs appear in GSC alongside the clean URLs | I41: Indexing | P41: =IFERROR(N41/O41,"") | Q41: Critical | R41: High | S41: M | T41: 301 all browse_*.cfm?id URLs to canonical clean URLs; add canonical | U41: Dev | W41: 46311 | X41: Identified | AB41: Duplicate URLs in GSC to 0 | AC41: From GSC export 6 Oct 2026 | AF41: Sample from top-1,000 pages only | AG41: 46308
...

Sheet Technical SEO
A1: Technical SEO
A2: Audit checklist. Results from the 6 Oct 2026 crawl of 17 templates; 'Not yet' items need the full crawl.
A4: Area | B4: Check | C4: Result (6 Oct 2026) | D4: Tracker ID / action | E4: Planned week | F4: Status | G4: Owner | H4: Notes
A5: Crawling | B5: Full JS-rendered crawl of all templates | C5: Not yet run | D5: Run Screaming Frog/Semrush Site Audit | E5: Week 1 | F5: Identified
A6: Indexability | B6: Canonicals | C6: Fail: 0 of 17 sampled | D6: T1 | E6: Week 1 | F6: Identified
A7: Indexability | B7: Host consolidation (apex/www/http) | C7: Fail: both hosts 200, http 302 | D7: T2 | E7: Week 1 | F7: Identified
A8: Indexability | B8: Soft 404 / invalid IDs | C8: Fail | D8: T3, T4 | E8: Week 1 | F8: Identified
A9: robots.txt | B9: Sitemap directive | C9: Fail: missing | D9: T7 | E9: Week 2 | F9: Identified
A10: robots.txt | B10: Blocks only low-value paths (/booking/, /admin/, /tools/, /data/, /cfc/) | C10: Pass | D10: Keep; decide GPTBot/ClaudeBot/Google-Extended policy | E10: Week 2 | F10: Completed
A11: XML sitemap | B11: Coverage by page type | C11: Fail: 14 URLs | D11: T5 | E11: Week 2 | F11: Identified
A12: XML sitemap | B12: Real lastmod | C12: Fail: identical date on all URLs | D12: T5 | E12: Week 2 | F12: Identified
A13: Duplicate content | B13: Duplicate hubs and chains | C13: Fail | D13: T6 | E13: Week 2 | F13: Identified
A14: Redirects | B14: Redirect chains and 302s | C14: Not yet crawled | D14: Crawl; map | E14: Week 1 | F14: Identified
A15: Links | B15: Broken internal links (footer /sitemap/) | C15: Fail: 404 | D15: T8 | E15: Week 2 | F15: Identified
A16: Faceted navigation | B16: Flight-time, distance, chain, country, region, city filters | C16: Not yet crawled | D16: List parameters; noindex/disallow policy | E16: Week 2 | F16: Identified
... A27: Cookies | B27: Persistent CFID on every request | C27: Fail | D27: T12 | E27: Week 4 | F27: Identified

Sheet Keywords
A1: Keywords
A2: Native Spanish keyword framework. Volume and difficulty: fill from Semrush (blank until data available). Score = Demand x Intent x Value x Probability / Effort.
A4: Keyword | B4: Market | C4: Intent | D4: Cluster | E4: Target page | F4: Search volume | G4: Keyword difficulty | H4: Demand (1-5) | I4: Intent (1-5) | J4: Value (1-5) | K4: Probability (1-5) | L4: Effort (1-5) | M4: Opportunity score | N4: Bucket | O4: Current position | P4: Master ID | R4: Bucket rule (editable): Quick win = score>=100 and effort<=2; Strategic = score>=100; Long-term = 30-99; else Low/avoid
A5: hoteles de lujo en Miami | B5: United States - Spanish | C5: Destination + luxury | D5: City hub | E5: Miami hub | M5: =IF(COUNT(H5:L5)=5,H5*I5*J5*K5/L5,"") | N5: =IF(M5="","",IF(AND(M5>=100,L5<=2),"Quick win",IF(M5>=100,"Strategic priority",IF(M5>=30,"Long-term investment","Low priority / avoid"))))
A6: hoteles cinco estrellas Nueva York | B6: United States - Spanish | C6: Destination + luxury | D6: City hub | E6: New York hub | M6: =IF(COUNT(H6:L6)=5,H6*I6*J6*K6/L6,"") | N6: =IF(M6="","",IF(AND(M6>=100,L6<=2),"Quick win",IF(M6>=100,"Strategic priority",IF(M6>=30,"Long-term investment","Low priority / avoid"))))
A7: hoteles de lujo en Madrid | B7: Spain | C7: Destination + luxury | D7: City hub | E7: Madrid hub | M7: =IF(COUNT(H7:L7)=5,H7*I7*J7*K7/L7,"") | N7: =IF(M7="","",IF(AND(M7>=100,L7<=2),"Quick win",IF(M7>=100,"Strategic priority",IF(M7>=30,"Long-term investment","Low priority / avoid"))))
A8: resorts de lujo Cancún | B8: Mexico | C8: Destination + luxury | D8: City hub | E8: Cancún hub | M8: =IF(COUNT(H8:L8)=5,H8*I8*J8*K8/L8,"") | N8: =IF(M8="","",IF(AND(M8>=100,L8<=2),"Quick win",IF(M8>=100,"Strategic priority",IF(M8>=30,"Long-term investment","Low priority / avoid"))))
A9: hoteles Four Seasons | B9: United States - Spanish | C9: Brand | D9: Chain | E9: /chains/2/four_seasons.html | M9: =IF(COUNT(H9:L9)=5,H9*I9*J9*K9/L9,"") | N9: =IF(M9="","",IF(AND(M9>=100,L9<=2),"Quick win",IF(M9>=100,"Strategic priority",IF(M9>=30,"Long-term investment","Low priority / avoid"))))
A10: ¿Cómo conseguir beneficios VIP en Four Seasons? | B10: All Spanish | C10: Informational | D10: AEO | E10: Four Seasons chain page | M10: =IF(COUNT(H10:L10)=5,H10*I10*J10*K10/L10,"") | N10: =IF(M10="","",IF(AND(M10>=100,L10<=2),"Quick win",IF(M10>=100,"Strategic priority",IF(M10>=30,"Long-term investment","Low priority / avoid"))))
A11: mejores hoteles para luna de miel | B11: All Spanish | C11: Commercial investigation | D11: Collection | E11: Luna de miel collection | M11: =IF(COUNT(H11:L11)=5,H11*I11*J11*K11/L11,"") | N11: =IF(M11="","",IF(AND(M11>=100,L11<=2),"Quick win",IF(M11>=100,"Strategic priority",IF(M11>=30,"Long-term investment","Low priority / avoid"))))
M12: =IF(COUNT(H12:L12)=5,H12*I12*J12*K12/L12,"") | N12: =IF(M12="","",IF(AND(M12>=100,L12<=2),"Quick win",IF(M12>=100,"Strategic priority",IF(M12>=30,"Long-term investment","Low priority / avoid"))))
M13: =IF(COUNT(H13:L13)=5,H13*I13*J13*K13/L13,"") | N13: =IF(M13="","",IF(AND(M13>=100,L13<=2),"Quick win",IF(M13>=100,"Strategic priority",IF(M13>=30,"Long-term investment","Low priority / avoid"))))
M14: =IF(COUNT(H14:L14)=5,H14*I14*J14*K14/L14,"") | N14: =IF(M14="","",IF(AND(M14>=100,L14<=2),"Quick win",IF(M14>=100,"Strategic priority",IF(M14>=30,"Long-term investment","Low priority / avoid"))))
M15: =IF(COUNT(H15:L15)=5,H15*I15*J15*K15/L15,"") | N15: =IF(M15="","",IF(AND(M15>=100,L15<=2),"Quick win",IF(M15>=100,"Strategic priority",IF(M15>=30,"Long-term investment","Low priority / avoid"))))
M16: =IF(COUNT(H16:L16)=5,H16*I16*J16*K16/L16,"") | N16: =IF(M16="","",IF(AND(M16>=100,L16<=2),"Quick win",IF(M16>=100,"Strategic priority",IF(M16>=30,"Long-term investment","Low priority / avoid"))))
M17: =IF(COUNT(H17:L17)=5,H17*I17*J17*K17/L17,"") | N17: =IF(M17="","",IF(AND(M17>=100,L17<=2),"Quick win",IF(M17>=100,"Strategic priority",IF(M17>=30,"Long-term investment","Low priority / avoid"))))
M18: =IF(COUNT(H18:L18)=5,H18*I18*J18*K18/L18,"") | N18: =IF(M18="","",IF(AND(M18>=100,L18<=2),"Quick win",IF(M18>=100,"Strategic priority",IF(M18>=30,"Long-term investment","Low priority / avoid"))))
M19: =IF(COUNT(H19:L19)=5,H19*I19*J19*K19/L19,"") | N19: =IF(M19="","",IF(AND(M19>=100,L19<=2),"Quick win",IF(M19>=100,"Strategic priority",IF(M19>=30,"Long-term investment","Low priority / avoid"))))
M20: =IF(COUNT(H20:L20)=5,H20*I20*J20*K20/L20,"") | N20: =IF(M20="","",IF(AND(M20>=100,L20<=2),"Quick win",IF(M20>=100,"Strategic priority",IF(M20>=30,"Long-term investment","Low priority / avoid"))))
M21: =IF(COUNT(H21:L21)=5,H21*I21*J21*K21/L21,"") | N21: =IF(M21="","",IF(AND(M21>=100,L21<=2),"Quick win",IF(M21>=100,"Strategic priority",IF(M21>=30,"Long-term investment","Low priority / avoid"))))
M22: =IF(COUNT(H22:L22)=5,H22*I22*J22*K22/L22,"") | N22: =IF(M22="","",IF(AND(M22>=100,L22<=2),"Quick win",IF(M22>=100,"Strategic priority",IF(M22>=30,"Long-term investment","Low priority / avoid"))))
M23: =IF(COUNT(H23:L23)=5,H23*I23*J23*K23/L23,"") | N23: =IF(M23="","",IF(AND(M23>=100,L23<=2),"Quick win",IF(M23>=100,"Strategic priority",IF(M23>=30,"Long-term investment","Low priority / avoid"))))
... M304: =IF(COUNT(H304:L304)=5,H304*I304*J304*K304/L304,"") | N304: =IF(M304="","",IF(AND(M304>=100,L304<=2),"Quick win",IF(M304>=100,"Strategic priority",IF(M304>=30,"Long-term investment","Low priority / avoid"))))

Sheet Rankings
A1: Rankings
A2: Weekly positions per keyword and market (Semrush position tracking). Enter one column per week.
A4: Keyword | B4: Market | C4: Country database | D4: Target URL | E4: Baseline position | F4: Wk 1 | G4: Wk 2 | H4: Wk 3 | I4: Wk 4 | J4: Latest | K4: Change vs baseline | L4: SERP feature | M4: Master ID
J5: =IF(COUNT(F5:I5)=0,"",LOOKUP(2,1/ISNUMBER(F5:I5),F5:I5)) | K5: =IF(OR(E5="",J5=""),"",E5-J5)
J6: =IF(COUNT(F6:I6)=0,"",LOOKUP(2,1/ISNUMBER(F6:I6),F6:I6)) | K6: =IF(OR(E6="",J6=""),"",E6-J6)
J7: =IF(COUNT(F7:I7)=0,"",LOOKUP(2,1/ISNUMBER(F7:I7),F7:I7)) | K7: =IF(OR(E7="",J7=""),"",E7-J7)
J8: =IF(COUNT(F8:I8)=0,"",LOOKUP(2,1/ISNUMBER(F8:I8),F8:I8)) | K8: =IF(OR(E8="",J8=""),"",E8-J8)
J9: =IF(COUNT(F9:I9)=0,"",LOOKUP(2,1/ISNUMBER(F9:I9),F9:I9)) | K9: =IF(OR(E9="",J9=""),"",E9-J9)
J10: =IF(COUNT(F10:I10)=0,"",LOOKUP(2,1/ISNUMBER(F10:I10),F10:I10)) | K10: =IF(OR(E10="",J10=""),"",E10-J10)
J11: =IF(COUNT(F11:I11)=0,"",LOOKUP(2,1/ISNUMBER(F11:I11),F11:I11)) | K11: =IF(OR(E11="",J11=""),"",E11-J11)
J12: =IF(COUNT(F12:I12)=0,"",LOOKUP(2,1/ISNUMBER(F12:I12),F12:I12)) | K12: =IF(OR(E12="",J12=""),"",E12-J12)
J13: =IF(COUNT(F13:I13)=0,"",LOOKUP(2,1/ISNUMBER(F13:I13),F13:I13)) | K13: =IF(OR(E13="",J13=""),"",E13-J13)
J14: =IF(COUNT(F14:I14)=0,"",LOOKUP(2,1/ISNUMBER(F14:I14),F14:I14)) | K14: =IF(OR(E14="",J14=""),"",E14-J14)
J15: =IF(COUNT(F15:I15)=0,"",LOOKUP(2,1/ISNUMBER(F15:I15),F15:I15)) | K15: =IF(OR(E15="",J15=""),"",E15-J15)
J16: =IF(COUNT(F16:I16)=0,"",LOOKUP(2,1/ISNUMBER(F16:I16),F16:I16)) | K16: =IF(OR(E16="",J16=""),"",E16-J16)
... J304: =IF(COUNT(F304:I304)=0,"",LOOKUP(2,1/ISNUMBER(F304:I304),F304:I304)) | K304: =IF(OR(E304="",J304=""),"",E304-J304)

Sheet Content
A1: Content
A2: Guides, comparisons, FAQs and hub support pages.
A4: Title (Spanish) | B4: URL | C4: Hub | D4: Content type | E4: Target keyword | F4: Author/expert | G4: Publish date | H4: Last reviewed | I4: Next refresh | J4: Status | K4: Impressions (90d) | L4: Clicks (90d) | M4: Master ID
A5: Hoteles de lujo en Madrid | B5: (new) | C5: Madrid | D5: City hub | E5: hoteles de lujo en Madrid | J5: Planned
A6: Dónde alojarse en Madrid: Salamanca, Centro y Retiro | B6: (new) | C6: Madrid | D6: Guide | E6: dónde alojarse en Madrid | J6: Planned
A7: Four Seasons vs. Ritz-Carlton | B7: (new) | C7: Chains | D7: Comparison | E7: Four Seasons vs Ritz Carlton | J7: Planned
A8: Hoteles de lujo en Islas Turcas y Caicos (Turks and Caicos) | B8: /hoteles-de-lujo/islas-turcas-y-caicos/ | C8: Turks & Caicos | D8: City/country hub | E8: hoteles en islas turcas y caicos | J8: Waiting for Client | M8: Z1
A9: Hoteles Four Seasons: 141 hoteles con desayuno para dos y crédito de hotel | B9: /hoteles-four-seasons/ | C9: Chains | D9: Chain page | E9: hoteles four seasons | J9: Waiting for Client | M9: Z2
A10: Four Seasons vs Ritz-Carlton: diferencias, beneficios y cuál elegir | B10: /guias/four-seasons-vs-ritz-carlton/ (new, after in-place fixes) | C10: Chains | D10: Comparison | E10: four seasons vs ritz carlton | J10: Waiting for Client | M10: Z22-Z23
A11: Hoteles de lujo en Londres | B11: /cities/150/london.html (in place) | C11: Destinations | D11: City hub | E11: hoteles en londres | J11: Waiting for Client | M11: Z32, Z34
A12: Hoteles Aman: 20 resorts con desayuno para dos y crédito de hotel | B12: /chains/21/Aman_Resorts.html (in place) | C12: Chains | D12: Chain page | E12: hoteles aman | J12: Waiting for Client | M12: Z31, Z35
A13: Hoteles de lujo en París | B13: /cities/207/paris.html (in place) | C13: Destinations | D13: City hub | E13: hoteles en parís | J13: Waiting for Client | M13: Z36
A14: Hoteles Fairmont: 79 hoteles con desayuno para dos y crédito de hotel | B14: /collection/1/ (in place, clean slug) | C14: Chains | D14: Chain page | E14: hoteles fairmont | J14: Waiting for Client | M14: Z33, Z37, Z38
A15: Hoteles Raffles: 21 hoteles con desayuno para dos y crédito de hotel | B15: /collection/11/ (in place, clean slug) | C15: Chains | D15: Chain page | E15: hoteles raffles | J15: Waiting for Client | M15: Z37, Z39
A16: Hoteles Bulgari: 9 hoteles con desayuno para dos y crédito de hotel | B16: /collection/71/ (in place, clean slug) | C16: Chains | D16: Chain page | E16: hoteles bulgari | J16: Waiting for Client | M16: Z39, Z40
A17: Hoteles The Peninsula: 12 hoteles con desayuno para dos y crédito de hotel | B17: /collection/9/ (in place, clean slug) | C17: Chains | D17: Chain page | E17: hoteles peninsula | J17: Waiting for Client | M17: Z39, Z41
A18: Hoteles Kimpton: 28 hoteles con desayuno para dos y crédito de hotel | B18: /collection/87/ (in place, clean slug) | C18: Chains | D18: Chain page | E18: hoteles kimpton | J18: Waiting for Client | M18: Z39, Z43
A19: Hoteles Dorchester Collection: 9 hoteles con desayuno para dos y crédito de hotel | B19: /collection/37/ (in place, clean slug) | C19: Chains | D19: Chain page | E19: dorchester collection | J19: Waiting for Client | M19: Z39, Z42
... A41: Hoteles The Unbound Collection: 24 hoteles con desayuno para dos y crédito de hotel | B41: /collection/65/ (clean slug, 301 from the Hyatt Prive slug) | C41: Chains | D41: Chain page | E41: the unbound collection | J41: Waiting for Client | M41: Z39, Z64, Z65, Z66

Sheet Page Metadata
A1: Page Metadata (H1, SEO title, meta description)
A2: Drafts for pages we have written. Titles 60 characters or fewer; descriptions 155 or fewer (red = over). Lengths are formulas. Nothing is live. Source: content/page-metadata.csv
A4: Page | B4: URL | C4: H1 | D4: SEO title (<title>) | E4: Title chars | F4: Meta description | G4: Desc chars | H4: Target query | I4: Status | J4: Notes
A5: Home | B5: / | C5: (existing H1) | D5: Hoteles de lujo de 5 estrellas en el mundo | Solo5Estrellas | E5: =LEN(D5) -> 59 | F5: Reserve hoteles de lujo en todo el mundo con desayuno para dos, crédito de hotel y mejora de categoría. Solo5Estrellas, de Lorraine Travel desde 1948. | G5: =LEN(F5) -> 150 | H5: hoteles de lujo | I5: Waiting for Client | J5: Existing page; new title via fix 7
A6: Country: Islas Turcas y Caicos | B6: /countries/64/{slug} (301 from browse_country.cfm?countryid=64) | C6: Hoteles de lujo en Islas Turcas y Caicos (Turks and Caicos) | D6: Hoteles de lujo en Islas Turcas y Caicos | Solo5Estrellas | E6: =LEN(D6) -> 57 | F6: 15 hoteles de lujo en Islas Turcas y Caicos (Turks and Caicos): Grace Bay, islas privadas y villas. Compare zonas y reserve con desayuno para dos. | G6: =LEN(F6) -> 146 | H6: hoteles en islas turcas y caicos | I6: Waiting for Client | J6: Needs fact check and developer
A7: City: Nueva York | B7: /cities/192/new_york.html | C7: Hoteles de lujo en Nueva York | D7: Hoteles de lujo en Nueva York | Solo5Estrellas | E7: =LEN(D7) -> 46 | F7: Compare hoteles de lujo en Nueva York por zona: Midtown, Upper East Side, Tribeca, Brooklyn. Reserve con beneficios exclusivos de Solo5Estrellas. | G7: =LEN(F7) -> 145 | H7: hoteles en nueva york | I7: Waiting for Client | J7: Needs fact check and developer
A8: City: Miami | B8: /cities/168/Miami.html | C8: Hoteles de lujo en Miami | D8: Hoteles de lujo en Miami | Solo5Estrellas | E8: =LEN(D8) -> 41 | F8: Compare hoteles de lujo en Miami por zona: South Beach, Mid-Beach, Brickell, Coconut Grove y Coral Gables. Reserve con beneficios de Solo5Estrellas. | G8: =LEN(F8) -> 148 | H8: hoteles en miami | I8: Waiting for Client | J8: Needs fact check and developer
A9: City: Londres | B9: /cities/150/london.html | C9: Hoteles de lujo en Londres | D9: Hoteles de lujo en Londres | Solo5Estrellas | E9: =LEN(D9) -> 43 | F9: Compare hoteles de lujo en Londres por zona: Mayfair, St James's, Knightsbridge, Covent Garden y la City. Reserve con beneficios de Solo5Estrellas. | G9: =LEN(F9) -> 147 | H9: hoteles en londres | I9: Waiting for Client | J9: Needs fact check and developer
A10: City: París | B10: /cities/207/paris.html | C10: Hoteles de lujo en París | D10: Hoteles de lujo en París | Solo5Estrellas | E10: =LEN(D10) -> 41 | F10: Compare hoteles de lujo en París por barrio: Triángulo de Oro, Tullerías, Saint-Germain y Torre Eiffel. Reserve con beneficios de Solo5Estrellas. | G10: =LEN(F10) -> 145 | H10: hoteles en parís | I10: Waiting for Client | J10: Needs fact check and developer
A11: Chain: Four Seasons | B11: /chains/2/four_seasons.html (one canonical; /hoteles-four-seasons/ only if the developer prefers a new URL) | C11: Hoteles Four Seasons: 141 hoteles con desayuno para dos y crédito de hotel | D11: Hoteles Four Seasons: beneficios exclusivos | Solo5Estrellas | E11: =LEN(D11) -> 60 | F11: Reserve 141 hoteles Four Seasons en 47 países y territorios con desayuno para dos, crédito de hotel y mejora de categoría, a la misma tarifa publicada. | G11: =LEN(F11) -> 151 | H11: hoteles four seasons | I11: Waiting for Client | J11: Needs fact check and developer
A12: Chain: Aman | B12: /chains/21/Aman_Resorts.html (one canonical) | C12: Hoteles Aman: 20 resorts con desayuno para dos y crédito de hotel | D12: Hoteles Aman: beneficios exclusivos | Solo5Estrellas | E12: =LEN(D12) -> 52 | F12: Reserve 20 hoteles Aman en 14 países con desayuno para dos, crédito de hotel y mejora de categoría, a la misma tarifa publicada. | G12: =LEN(F12) -> 128 | H12: hoteles aman | I12: Waiting for Client | J12: Needs fact check and developer
A13: Chain: Fairmont | B13: /collection/1/ (clean slug, 301 from the HERA-Program slugs) | C13: Hoteles Fairmont: 79 hoteles con desayuno para dos y crédito de hotel | D13: Hoteles Fairmont: beneficios exclusivos | Solo5Estrellas | E13: =LEN(D13) -> 56 | F13: Reserve 79 hoteles Fairmont en 29 países y territorios con desayuno para dos, crédito de hotel y mejora de categoría, a la misma tarifa publicada. | G13: =LEN(F13) -> 146 | H13: hoteles fairmont | I13: Waiting for Client | J13: Needs fact check and developer
A14: Chain: Raffles | B14: /collection/11/ (clean slug, 301 from the Accor-HERA slug) | C14: Hoteles Raffles: 21 hoteles con desayuno para dos y crédito de hotel | D14: Hoteles Raffles: beneficios exclusivos | Solo5Estrellas | E14: =LEN(D14) -> 55 | F14: Reserve 21 hoteles Raffles en 16 países con desayuno para dos, crédito de hotel y mejora de categoría, a la misma tarifa publicada. | G14: =LEN(F14) -> 131 | H14: hoteles raffles | I14: Waiting for Client | J14: Needs fact check and developer
A15: Chain: Bulgari | B15: /collection/71/ (clean slug, 301 from the Marriott-STARS-Program slugs) | C15: Hoteles Bulgari: 9 hoteles con desayuno para dos y crédito de hotel | D15: Hoteles Bulgari: beneficios exclusivos | Solo5Estrellas | E15: =LEN(D15) -> 55 | F15: Reserve 9 hoteles Bulgari en 7 países con desayuno para dos, crédito de hotel y mejora de categoría, y siga sumando puntos Marriott Bonvoy. | G15: =LEN(F15) -> 139 | H15: hoteles bulgari | I15: Waiting for Client | J15: Needs fact check and developer
A16: Chain: Peninsula | B16: /collection/9/ (clean slug, 301 from the Pen-Club-Program slugs) | C16: Hoteles The Peninsula: 12 hoteles con desayuno para dos y crédito de hotel | D16: Hoteles Peninsula: beneficios exclusivos | Solo5Estrellas | E16: =LEN(D16) -> 57 | F16: Reserve 12 hoteles The Peninsula en 8 países con desayuno para dos, crédito de hotel y mejora de categoría, a la misma tarifa publicada. | G16: =LEN(F16) -> 136 | H16: hoteles peninsula | I16: Waiting for Client | J16: Needs fact check and developer
... A43: Chain: The Unbound Collection | B43: /collection/65/ (clean slug, 301 from the Hyatt Prive slug) | C43: Hoteles The Unbound Collection: 24 hoteles con desayuno para dos y crédito de hotel | D43: Hoteles The Unbound Collection | Solo5Estrellas | E43: =LEN(D43) -> 47 | F43: Reserve 24 hoteles The Unbound Collection en 10 países con desayuno para dos, crédito de hotel y mejora de categoría, a la misma tarifa publicada. | G43: =LEN(F43) -> 146 | H43: unbound collection | I43: Waiting for Client | J43: Needs fact check and developer

Sheet Keyword Map
A1: Keyword to Page Map (Search Console, 29 Jan to 6 Oct 2026)
A2: Query families from the 6,953 exported queries, each assigned to one target page. First match wins (e.g. 'four seasons madrid' counts under Four Seasons). P1 = act first. Source: content/keyword-page-map.csv
A4: Family | B4: Queries | C4: Clicks | D4: Impressions | E4: Avg position | F4: Top queries | G4: Target page | H4: Current state | I4: Action | J4: Priority | K4: Ref
A5: Islas Turcas y Caicos | B5: 125 | C5: 6 | D5: 5779 | E5: 13.7 | F5: hoteles en islas turcas y caicos; hoteles en turks and caicos; islas turcas y caicos hoteles | G5: /countries/64/{slug} (legacy: browse_country.cfm?countryid=64) | H5: Top landing page is on a legacy URL that serves home content | I5: 301 the legacy URL, publish hub copy there, fix Ambergris Cay text | J5: P1 | K5: Z1, Z28
A6: Londres | B6: 126 | C6: 0 | D6: 1038 | E6: 20.8 | F6: habitaciones en the chesterfield mayfair; hoteles de 5 estrellas en londres; dorchester collection | G6: City page /cities/{id}/ (ID from CMS) | H6: Queries for Mayfair, Dorchester, Chesterfield; Spanish and English | I6: City hub copy; Spanish place name 'Londres' | J6: P1 | K6: new
A7: Four Seasons | B7: 292 | C7: 0 | D7: 932 | E7: 25.2 | F7: four seasons madrid; four seasons puxi; four seasons | G7: /chains/2/four_seasons.html (and /collection/2/ variants) | H7: 3 URL variants; English title; position 25 | I7: One canonical, Spanish title, chain copy (141 hotels, 10 FAQ) | J7: P1 | K7: Z2, Z14
A8: Aman | B8: 98 | C8: 3 | D8: 895 | E8: 16.9 | F8: aman hotels; hoteles aman en el mundo; aman resorts | G8: /chains/21/Aman_Resorts.html | H8: 3 URL variants for ID 21 (812 + 331 + 47 impressions); position 17 | I8: One canonical; chain page copy modelled on Four Seasons; Aman hotel pages link up | J8: P1 | K8: new
A9: Miami | B9: 35 | C9: 0 | D9: 88 | E9: 31.4 | F9: hotel the miami beach; hotel beaux arts miami; the edition miami | G9: /cities/168/Miami.html | H9: Hub drafted; hotels split across city records | I9: Publish hub in place; related-areas block | J9: P1 | K9: Z18
A10: Nueva York | B10: 45 | C10: 0 | D10: 86 | E10: 26.6 | F10: hotel plaza new york; hotel plaza nueva york; casa cipriani new york | G10: /cities/192/new_york.html | H10: Head term has 103 impressions; hub drafted | I10: Publish hub in place | J10: P1 | K10: Z5
A11: Madrid | B11: 21 | C11: 0 | D11: 35 | E11: 27.7 | F11: hesperia madrid; hotel thompson madrid; hotel exclusivo madrid | G11: /hotels/3897/ (Four Seasons Hotel Madrid) and a Madrid city page | H11: 'four seasons madrid' is the top Four Seasons query; hotel page has no content | I11: Publish drafted hotel page; add Madrid city copy | J11: P1 | K11: Z14
A12: Fairmont | B12: 260 | C12: 0 | D12: 821 | E12: 39.8 | F12: fairmont hotels; fairmont hotels & resorts; fairmont hotels and resorts | G12: /collection/1/ (slug names a loyalty program: Fairmont_Hotels_under_Accor's_HERA_Program) | H12: Slug carries a partner-program name; 2 variants; position 40 | I12: Rename to a clean slug with a 301; chain copy; link from hotel pages | J12: P2 | K12: new
A13: París | B13: 128 | C13: 0 | D13: 530 | E13: 26.1 | F13: hoteles de 5 estrellas en parís; hotel san regis paris; hoteles 5 estrellas en paris | G13: City page /cities/{id}/ (ID from CMS) | H13: Queries like 'hoteles de 5 estrellas en parís'; position 26 | I13: City hub copy like Miami and New York | J13: P2 | K13: new
A14: Ritz-Carlton | B14: 204 | C14: 0 | D14: 489 | E14: 27.9 | F14: hotel ritz paris; nujuma a ritz-carlton reserve; mandarin oriental vs ritz carlton munich | G14: /chains/13/ritz_carlton.html | H14: Position 28; Hotel Arts Barcelona listed under it | I14: Chain copy; fix chain membership (Z22) | J14: P2 | K14: Z22
A15: Hyatt | B15: 224 | C15: 0 | D15: 466 | E15: 19.9 | F15: hyatt prive; park hyatt busan; grand hyatt tokyo | G15: Chain page (ID from CMS) | H15: Position 19; brand terms (Prive, Park Hyatt, Grand Hyatt) | I15: Chain copy; one canonical per brand | J15: P2 | K15: new
A16: Marriott / Kimpton / Peninsula brands | B16: 648 | C16: 1 | D16: 2418 | E16: 26.5 | F16: kimpton hotels; renaissance hotels; jw marriott guanacaste resort & spa | G16: Chain pages (IDs from CMS) | H16: Brand and program queries, positions mostly deep | I16: Chain copy after the first three chains | J16: P3 | K16: new
... A18: Barcelona | B18: 58 | C18: 0 | D18: 146 | E18: 33.6 | F18: hotel arts barcelona; hotel palace barcelona; sls barcelona | G18: City page /cities/{id}/ (ID from CMS) | H18: Position 34; Hotel Arts, Palace, SLS | I18: City hub copy | J18: P3 | K18: new
A19: Total | B19: =SUM(B5:B18) -> 2279 | C19: =SUM(C5:C18) -> 10 | D19: =SUM(D5:D18) -> 14056

Sheet Hotel Pages
A1: Hotel Pages
A2: Hotel-level work. Revenue tier comes from the client's top-100 list.
A4: Hotel ID | B4: Hotel | C4: City | D4: Country | E4: Chain | F4: URL | G4: Revenue tier (A/B/C) | H4: Unique title | I4: Unique description | J4: Unique body (words) | K4: Verified perks block | L4: FAQ on page | M4: Hotel schema | N4: Status | O4: Impressions (90d) | P4: Clicks (90d) | Q4: Inquiries (90d) | R4: Master ID
A5: 6494 | B5: 1 Hotel Brooklyn Bridge | C5: New York | D5: Estados Unidos | F5: /hotels/6494/1-hotel-brooklyn-bridge.html | H5: No | I5: No | J5: ~1,400 | K5: No | L5: Yes (sales-line answers) | M5: No | N5: Identified

Sheet Destination Pages
A1: Destination Pages
A2: City, country, region, chain and collection hubs.
A4: Hub | B4: Type | C4: URL (current or planned) | D4: Market priority | E4: Status | F4: Direct answer | G4: Selection table | H4: Neighborhood guide | I4: FAQ (5-8) | J4: Schema | K4: Keywords in top 10 | L4: Clicks (90d) | M4: Inquiries (90d) | N4: Master ID
A5: Hoteles de lujo en Miami | B5: City | C5: (new, Spanish path) | D5: United States - Spanish | E5: Planned
A6: Hoteles de lujo en Nueva York | B6: City | C6: /cities/192/new_york.html | D6: United States - Spanish | E6: Identified
A7: Hoteles de lujo en Cancún | B7: City | C7: /cities/44/cancun.html | D7: Mexico | E7: Identified
A8: Hoteles de lujo en Madrid | B8: City | C8: (new) | D8: Spain | E8: Planned
A9: Hoteles Four Seasons | B9: Chain | C9: /chains/2/four_seasons.html | D9: United States - Spanish | E9: Identified
A10: Hoteles de lujo en Europa | B10: Region | C10: /regions/8/europe.html | D10: Spain | E10: Identified
A11: Hoteles de lujo en Islas Turcas y Caicos | B11: Country | C11: /hoteles-de-lujo/islas-turcas-y-caicos/ (replaces browse_country.cfm?countryid=64) | D11: Mexico | E11: Waiting for Client | F11: Yes | G11: Yes (15 hotels) | H11: Yes (6 zones) | I11: Yes (8) | J11: Drafted (BreadcrumbList, ItemList, FAQPage) | L11: 29 | N11: Z1, X1
A12: Hoteles Four Seasons | B12: Chain | C12: /hoteles-four-seasons/ (replaces /chains/2/ and /collection/2/ variants) | D12: United States - Spanish | E12: Waiting for Client | F12: Yes | G12: Yes (141 hotels) | H12: Destination blocks | I12: Yes (10) | J12: Drafted (BreadcrumbList, ItemList, FAQPage) | L12: 0 | N12: Z2, Z14-Z17
A13: Hoteles de lujo en Nueva York | B13: City | C13: /cities/192/new_york.html (in place) | D13: United States - Spanish | E13: Waiting for Client | F13: Yes | G13: Yes (hotels by zone) | H13: Yes (zones) | I13: Yes (8) | J13: Drafted (BreadcrumbList, ItemList, FAQPage) | L13: 0 | N13: Z5, Z18-Z21
A14: Hoteles de lujo en Miami | B14: City | C14: /cities/168/Miami.html (in place) | D14: United States - Spanish | E14: Waiting for Client | F14: Yes | G14: Yes (hotels by zone) | H14: Yes (zones) | I14: Yes (8) | J14: Drafted (BreadcrumbList, ItemList, FAQPage) | L14: 0 | N14: Z5, Z18-Z21
A15: Hoteles de lujo en Londres | B15: City | C15: /cities/150/london.html (in place) | D15: Spain / US - Spanish | E15: Waiting for Client | F15: Yes | G15: Yes (hotels by zone) | H15: Yes (8 zones) | I15: Yes (8) | J15: Drafted (BreadcrumbList, ItemList, FAQPage) | L15: 0 | M15: 1038 | N15: Z32, Z34
A16: Hoteles Aman | B16: Chain | C16: /chains/21/Aman_Resorts.html (in place) | D16: Spain / US - Spanish | E16: Waiting for Client | F16: Yes | G16: Yes (20 hotels) | H16: Destination blocks | I16: Yes (9) | J16: Drafted (BreadcrumbList, ItemList, FAQPage) | L16: 0 | M16: 890 | N16: Z31, Z35
A17: Hoteles de lujo en París | B17: City | C17: /cities/207/paris.html (in place) | D17: Spain / US - Spanish | E17: Waiting for Client | F17: Yes | G17: Yes (hotels by zone) | H17: Yes (7 groups) | I17: Yes (8) | J17: Drafted (BreadcrumbList, ItemList, FAQPage) | L17: 0 | M17: 530 | N17: Z36
A18: Hoteles Fairmont | B18: Chain | C18: /collection/1/ (in place, clean slug) | D18: Spain / US - Spanish | E18: Waiting for Client | F18: Yes | G18: Yes (79 hotels) | H18: Destination blocks | I18: Yes (9) | J18: Drafted (BreadcrumbList, ItemList, FAQPage) | L18: 0 | M18: 436 | N18: Z33, Z37, Z38
A19: Hoteles Raffles | B19: Chain | C19: /collection/11/ (in place, clean slug) | D19: Spain / US - Spanish | E19: Waiting for Client | F19: Yes | G19: Yes (21 hotels) | H19: Destination blocks | I19: Yes (9) | J19: Drafted (BreadcrumbList, ItemList, FAQPage) | L19: 0 | M19: 50 | N19: Z37, Z39
A20: Hoteles Bulgari | B20: Chain | C20: /collection/71/ (in place, clean slug) | D20: Spain / US - Spanish | E20: Waiting for Client | F20: Yes | G20: Yes (9 hotels) | H20: Destination blocks | I20: Yes (9) | J20: Drafted (BreadcrumbList, ItemList, FAQPage) | L20: 0 | M20: 305 | N20: Z39, Z40
A21: Hoteles The Peninsula | B21: Chain | C21: /collection/9/ (in place, clean slug) | D21: Spain / US - Spanish | E21: Waiting for Client | F21: Yes | G21: Yes (12 hotels) | H21: Destination blocks | I21: Yes (9) | J21: Drafted (BreadcrumbList, ItemList, FAQPage) | L21: 0 | M21: 474 | N21: Z39, Z41
A22: Hoteles Kimpton | B22: Chain | C22: /collection/87/ (in place, clean slug) | D22: Spain / US - Spanish | E22: Waiting for Client | F22: Yes | G22: Yes (28 hotels) | H22: Destination blocks | I22: Yes (9) | J22: Drafted (BreadcrumbList, ItemList, FAQPage) | L22: 0 | M22: 554 | N22: Z39, Z43
A23: Hoteles Dorchester Collection | B23: Chain | C23: /collection/37/ (in place, clean slug) | D23: Spain / US - Spanish | E23: Waiting for Client | F23: Yes | G23: Yes (9 hotels) | H23: Destination blocks | I23: Yes (9) | J23: Drafted (BreadcrumbList, ItemList, FAQPage) | L23: 0 | M23: 322 | N23: Z39, Z42
A24: Hoteles Taj | B24: Chain | C24: /collection/26/ (in place) | D24: Spain / US - Spanish | E24: Waiting for Client | F24: Yes | G24: Yes (12 hotels) | H24: Destination blocks | I24: Yes (9) | J24: Drafted (BreadcrumbList, ItemList, FAQPage) | L24: 0 | M24: 193 | N24: Z39, Z44
A25: Hoteles InterContinental | B25: Chain | C25: /collection/15/ (in place, clean slug) | D25: Spain / US - Spanish | E25: Waiting for Client | F25: Yes | G25: Yes (by country) | H25: Destination blocks | I25: Yes (9) | J25: Drafted (BreadcrumbList, ItemList, FAQPage) | L25: 0 | M25: 311 | N25: Z39, Z42
A26: Hoteles Renaissance | B26: Chain | C26: /collection/70/ (in place, clean slug) | D26: Spain / US - Spanish | E26: Waiting for Client | F26: Yes | G26: Yes (by country) | H26: Destination blocks | I26: Yes (9) | J26: Drafted (BreadcrumbList, ItemList, FAQPage) | L26: 0 | M26: 245 | N26: Z39, Z42
... A45: Hoteles The Unbound Collection | B45: Chain | C45: /collection/65/ (clean slug, 301 from the Hyatt Prive slug) | D45: US / China - Spanish | E45: Waiting for Client | F45: Yes | G45: Yes (24 hotels) | H45: Destination blocks | I45: Yes (9) | J45: Drafted (BreadcrumbList, ItemList, FAQPage) | L45: 0 | M45: 0 | N45: Z39, Z64, Z65, Z66

Sheet U.S. Hispanic SEO
A1: U.S. Hispanic SEO
A2: U.S. Spanish performance by state/city. Isolate with GA4 language es* + country US; in GSC use country US + Spanish query classification.
A4: State | B4: Metro | C4: Query / cluster | D4: Landing page | E4: Impressions | F4: Clicks | G4: CTR | H4: Avg. position | I4: Inquiries | J4: Doorway-guardrail check (tools, own recs, distinct demand) | K4: Master ID
A5: FL | B5: Miami / South Florida | C5: hoteles de lujo en Miami | D5: Miami hub | G5: =IFERROR(F5/E5,"")
A6: NY | B6: New York | C6: hoteles cinco estrellas Nueva York | D6: New York hub | G6: =IFERROR(F6/E6,"")
A7: NV | B7: Las Vegas | C7: hoteles de lujo Las Vegas | D7: Las Vegas hub | G7: =IFERROR(F7/E7,"")
A8: TX | B8: Houston | C8: escapadas de lujo desde Houston | D8: (origin-city guide - validate demand first) | G8: =IFERROR(F8/E8,"")
A9: TX | B9: Dallas | C9: hoteles de lujo cerca de Dallas | D9: (origin-city guide - validate demand first) | G9: =IFERROR(F9/E9,"")
G10: =IFERROR(F10/E10,"")
G11: =IFERROR(F11/E11,"")
G12: =IFERROR(F12/E12,"")
G13: =IFERROR(F13/E13,"")
G14: =IFERROR(F14/E14,"")
G15: =IFERROR(F15/E15,"")
G16: =IFERROR(F16/E16,"")
G17: =IFERROR(F17/E17,"")
G18: =IFERROR(F18/E18,"")
G19: =IFERROR(F19/E19,"")
G20: =IFERROR(F20/E20,"")
G21: =IFERROR(F21/E21,"")
... G204: =IFERROR(F204/E204,"")

Sheet International Markets
A1: International Markets (Market Dashboard)
A2: Baseline from GSC (29 Jan - 3 Oct 2026). Enter later months in new columns or copy the tab. CTR, share and growth are formulas. Tier = working decision, see Notes.
A4: Market | B4: Tier | C4: Impressions | D4: Clicks | E4: CTR | F4: Avg. position | G4: Share of impressions | H4: Share of clicks | I4: Ranking keywords | J4: Conversions | K4: Top destinations | L4: MoM growth in clicks | M4: Prior-month clicks | N4: Decision gate / notes
A5: United States - Spanish | B5: 1 | C5: 5037 | D5: 15 | E5: =IFERROR(D5/C5,"") -> 0.0029779631 | F5: 24.48 | G5: =IFERROR(C5/$C$16,"") -> 0.10988939 | H5: =IFERROR(D5/$D$16,"") -> 0.12096774 | L5: =IF(OR(M5="",M5=0,D5=""),"",D5/M5-1) | N5: Position 24.5: weakest ranking among large markets; Miami, New York, Las Vegas hubs are the priority.
A6: Mexico | B6: 1 | C6: 7753 | D6: 14 | E6: =IFERROR(D6/C6,"") -> 0.0018057526 | F6: 14.7 | G6: =IFERROR(C6/$C$16,"") -> 0.16914283 | H6: =IFERROR(D6/$D$16,"") -> 0.11290323 | L6: =IF(OR(M6="",M6=0,D6=""),"",D6/M6-1) | N6: 16.9% of impressions, 11.3% of clicks; Cancún and Los Cabos hubs.
A7: Spain | B7: 1 | C7: 13720 | D7: 37 | E7: =IFERROR(D7/C7,"") -> 0.002696793 | F7: 18.27 | G7: =IFERROR(C7/$C$16,"") -> 0.29932151 | H7: =IFERROR(D7/$D$16,"") -> 0.2983871 | L7: =IF(OR(M7="",M7=0,D7=""),"",D7/M7-1) | N7: Largest market: 29.9% of impressions and clicks at position 18.3; Madrid, Barcelona, Europe hubs. Confirm EUR booking path.
A8: Argentina | B8: 2 | C8: 4176 | D8: 10 | E8: =IFERROR(D8/C8,"") -> 0.002394636 | F8: 11.3 | G8: =IFERROR(C8/$C$16,"") -> 0.091105439 | H8: =IFERROR(D8/$D$16,"") -> 0.080645161 | L8: =IF(OR(M8="",M8=0,D8=""),"",D8/M8-1) | N8: 9.1% of impressions at position 11.3 passes the 8-10% gate; promote to Tier 1 once a booking path is confirmed (currency controls).
A9: Peru | B9: 2 | C9: 1340 | D9: 6 | E9: =IFERROR(D9/C9,"") -> 0.0044776119 | F9: 11.99 | G9: =IFERROR(C9/$C$16,"") -> 0.029234025 | H9: =IFERROR(D9/$D$16,"") -> 0.048387097 | L9: =IF(OR(M9="",M9=0,D9=""),"",D9/M9-1) | N9: 2.9% of impressions, 4.8% of clicks; high click share. Reuse hubs, add Machu Picchu / Sacred Valley hotel content.
A10: Colombia | B10: 2 | C10: 1376 | D10: 4 | E10: =IFERROR(D10/C10,"") -> 0.0029069767 | F10: 11.68 | G10: =IFERROR(C10/$C$16,"") -> 0.030019417 | H10: =IFERROR(D10/$D$16,"") -> 0.032258065 | L10: =IF(OR(M10="",M10=0,D10=""),"",D10/M10-1) | N10: 3.0% of impressions at position 11.7.
